<robot name="my_robot">
  <link name="base_link"/>

  <joint name="joint1" type="revolute">
    <parent link="base_link"/>
    <child link="link1"/>
    <origin xyz="0 0 0.088" rpy="0 0 0"/>
    <axis xyz="0 0 1"/>
    <limit lower="0.1745" upper="2.9671" effort="1.47" velocity="1.0"/>
  </joint>
  <link name="link1">
    <inertial><mass value="0.090"/><inertia ixx="0.001" iyy="0.001" izz="0.001" ixy="0" ixz="0" iyz="0"/></inertial>
  </link>

  <joint name="joint2" type="revolute">
    <parent link="link1"/>
    <child link="link2"/>
    <origin xyz="-0.022 0 0" rpy="0 -1.5707 0"/>
    <axis xyz="0 1 0"/>
    <limit lower="0.1745" upper="2.9671" effort="2.1" velocity="1.0"/>
  </joint>
  <link name="link2">
     <inertial><mass value="0.090"/><inertia ixx="0.001" iyy="0.001" izz="0.001" ixy="0" ixz="0" iyz="0"/></inertial>
  </link>

  <joint name="joint3" type="revolute">
    <parent link="link2"/>
    <child link="link3"/>
    <origin xyz="0.104 0 0" rpy="0 0 0"/>
    <axis xyz="0 -1 0"/>
    <limit lower="0.1745" upper="2.9671" effort="1.47" velocity="1.0"/>
  </joint>
  <link name="link3">
     <inertial><mass value="0.090"/><inertia ixx="0.001" iyy="0.001" izz="0.001" ixy="0" ixz="0" iyz="0"/></inertial>
  </link>

  <joint name="joint4" type="revolute">
    <parent link="link3"/>
    <child link="link4"/>
    <origin xyz="0.125 0 0" rpy="0 0 0"/>
    <axis xyz="0 1 0"/>
    <limit lower="0.1745" upper="2.9671" effort="1.47" velocity="1.0"/>
  </joint>
  <link name="link4">
     <inertial><mass value="0.090"/><inertia ixx="0.001" iyy="0.001" izz="0.001" ixy="0" ixz="0" iyz="0"/></inertial>
  </link>

  <joint name="joint5" type="revolute">
    <parent link="link4"/>
    <child link="link5"/>
    <origin xyz="0 0 0" rpy="0 0 0"/>
    <axis xyz="1 0 0"/>
    <limit lower="0.1745" upper="2.9671" effort="1.47" velocity="1.0"/>
  </joint>
  <link name="link5">
     <inertial><mass value="0.050"/><inertia ixx="0.001" iyy="0.001" izz="0.001" ixy="0" ixz="0" iyz="0"/></inertial>
  </link>
  
  <joint name="tcp_joint" type="fixed">
    <parent link="link5"/>
    <child link="tcp"/>
    <origin xyz="0.162 0 0" rpy="0 0 0"/>
  </joint>
  <link name="tcp"/>
</robot>